# 🔧 Fix: Error del Daemon - TimeoutPIDLockFile

## ❌ Problema Original
```
Error starting daemon: 'str' object has no attribute 'TimeoutPIDLockFile'
```

## 🎯 Causa del Error

El problema estaba en la migración de `sander-daemon` a `python-daemon`. La nueva API funciona de manera diferente:

**❌ Código problemático:**
```python
from daemon import Daemon  # API antigua
daemon.pidfile.TimeoutPIDLockFile(self.pidfile)  # Incorrecto
```

**✅ Código corregido:**
```python
from daemon import DaemonContext
from daemon.pidfile import TimeoutPIDLockFile  # Import directo
```

## ✅ Solución Implementada

### 🔄 **Cambios en `usb_canary.py`:**

1. **Imports corregidos:**
```python
from daemon import DaemonContext
from daemon.pidfile import TimeoutPIDLockFile
import signal  # Agregado al inicio
```

2. **Nueva implementación del daemon:**
```python
def start(self):
    # Verificar si ya está corriendo
    if self._is_running():
        print("Daemon ya está ejecutándose")
        return 1
    
    try:
        # Crear el contexto del daemon correctamente
        pidfile = TimeoutPIDLockFile(self.pidfile)
        context = DaemonContext(
            pidfile=pidfile,
            working_directory=os.getcwd(),
            umask=0o002,
        )
        
        with context:
            self.run()
    except Exception as e:
        print(f"Error starting daemon: {e}")
        return 1
    return 0
```

3. **Funciones mejoradas:**
- `start()`: Verificación previa + contexto correcto
- `stop()`: Terminación graceful + forzada si es necesario
- `restart()`: Stop + Start con pausa
- `_is_running()`: Verificación de estado del daemon

### 🛠️ **Características nuevas:**

- ✅ **Verificación de estado**: No permite múltiples instancias
- ✅ **Terminación graceful**: SIGTERM primero, SIGKILL si es necesario
- ✅ **Limpieza automática**: Elimina PID files huérfanos
- ✅ **Mejor manejo de errores**: Mensajes informativos
- ✅ **Compatibilidad completa**: Con python-daemon 3.0+

## 🧪 Pruebas

Agregado `test_daemon.py` para verificar funcionamiento:

```bash
python3 test_daemon.py
```

**Salida esperada:**
```
🔍 Probando funcionalidad del daemon...
==================================================

🧪 Imports de daemon:
✅ Imports de daemon: OK

🧪 Creación de daemon:
✅ Creación de daemon: OK

🧪 Creación de PIDFile:
✅ Creación de PIDFile: OK

==================================================
🎉 Todas las pruebas pasaron (3/3)
✅ El daemon debería funcionar correctamente
```

## 🚀 Uso Correcto

```bash
# Iniciar el daemon
python3 usb_canary.py start

# Verificar estado
ps aux | grep usb_canary

# Parar el daemon
python3 usb_canary.py stop

# Reiniciar el daemon
python3 usb_canary.py restart
```

## 📋 Verificación de Instalación

Si sigues teniendo problemas, verifica:

```bash
# Versión de python-daemon
pip show python-daemon

# Debe ser >= 3.0.0
# Si no: pip install --upgrade python-daemon>=3.0.0
```

---

**✅ Fix aplicado y probado** - El error del daemon está resuelto.
